<mujoco model=''>

    <compiler inertiafromgeom='false' angle='degree' eulerseq='zyx' meshdir='../../minitaur-stl'/>
    <size nuser_actuator='1' nuser_sensor='1'/>
    <option timestep='0.0005' iterations='50' solver='PGS' gravity='0 0 -9.806'/>
    <!-- Timestep is set to 0.0005 because our controller runs at 2 kHz (-9.806) -->
    <!-- Larger values still have stable dynamics -->
    
    <visual>
        <quality shadowsize='4096'/>
        <map znear='0.05'/>
    </visual>
    
    <default>
        <joint limited='true'/>
        <geom contype='0' conaffinity='0' condim='1' solref=".005 1" solimp=".8 .8 .01" material='collision'/>
        <equality solref='0.005 1'/>
        <motor ctrllimited='true'/>
        <mesh scale='0.001 0.001 0.001'/>
        <default class='mesh-import'>
            <geom type='mesh' euler='0 90 90' material='cassie'/>
        </default>
    </default>
    
    <asset>
        <texture type='skybox' builtin='gradient' width='128' height='128' rgb1='0.725490196078431   0.403921568627451   1.000000000000000' rgb2='1.000000000000000   0.984313725490196   0.588235294117647'/>
        <texture name='plane' type='2d' builtin='checker'  rgb1='1 0 0' rgb2='1 1 0' width='128' height='128'/>
        <material name='plane' reflectance='0.0' texture='plane' texrepeat='4 4' texuniform='true'/>
        <material name='cassie' rgba='0.003921568627451   0.803921568627451   0.996078431372549 1'/>
        <material name='collision' rgba='0 1 0 0.1'/>
        <mesh name='thigh' file='thigh.STL'/>
        <mesh name='foot' file='foot.STL'/>
        <mesh name='calf1' file='calf.STL'/>
        <mesh name='calf2' file='ankle.STL'/>
    </asset>

    <worldbody>
        <geom type='plane' size='100 100 100' material='plane' condim='3' contype='1' conaffinity='1'/>
    
        <body name='minitaur' pos='0 0 0.3'>
            <site name="bodyref" size="0.1"/>
            <camera mode="fixed" pos="1.3 -0.7 0.25" xyaxes = ".4 1 0 -.3 0 1"/>
            
            <inertial pos='0 0 0' mass='5.755' diaginertia='0.005 0.005 0.005'/>
            <geom type='box' size='0.21 0.1 0.075' material='cassie'/>
    
            <!--Forward/Backward motion -->
            <joint type='slide' limited='false' axis='1 0 0'/>
    
            <!-- Up/Down motion -->
            <joint type='slide' limited='false' axis='0 0 1' ref='0.3'/>
    
            <!-- Left/Right motion -->
            <joint type='slide' limited='false' axis='0 1 0'/>
    
            <!-- Pitch only -->
            <joint type='hinge' limited='false' axis='0 1 0'/>
    
            <!-- Roll only -->
            <!--<joint type='hinge' limited='false' axis='1 0 0'/>-->
    
            <!-- Rotation -->
            <!--<joint type='ball' limited='false'/>-->
    
            <!-- front left -->
            <body pos='0.2 0.14 0'>
                <inertial pos='0 0 0' mass='0.0001' diaginertia='0.0000000001 0.0000000001 0.0000000001'/>
                <geom type='box' size='0.01 0.01 0.01'/>
            
                <!-- thigh 1 -->
                <body euler='0 0 0' pos='0 0 0'> 
                        <inertial pos='0.03848 0 0.00397' mass='0.03921' fullinertia='0.00000539488 0.00005606744 0.00006107051 0 0.00000009813 0'/>
                        <geom type='capsule' fromto='0 0 0 0.1 0 0' size='0.01'/>
                        <geom class='mesh-import' mesh='thigh' euler='180 90 90' pos='0.1 -0.005 0'/>
                        <joint name='thigh1FL_j' type='hinge' pos='0 0 0' axis='0 1 0' range='-180 180' ref='-90' armature='0.0001'/>
                    
                    <body name='calfFL_long' pos='0.1 -0.01 0' euler='0 120 0'>
                        <inertial pos='0.11635 0 0.00463' mass='0.05488' fullinertia='0.00000220501 0.00027791876 0.00027939897 0 0 0'/>
                        <geom type='capsule' fromto='0 0 0 0.24 0 0' size='0.01'/>
                        <geom type='cylinder' pos='0 -0.01 0' euler='0 0 90' size='0.015 0.005' condim='3' contype='2' conaffinity='2'/>
                        <geom class='mesh-import' mesh='calf2' euler='180 90 90' pos='0 -0.005 0'/>
                        <joint type='hinge' pos='0 0 0' axis='0 1 0' limited='false'/>
                    
                        <body pos='0.24 0 0'>
                            <inertial pos='0 0 0' mass='0'/>
                            <geom type='sphere' size='0.015' contype='1' conaffinity='1'/>
                            <geom class='mesh-import' mesh='foot' euler='90 0 0' pos='0.005 0 0'/>
                        </body>
                    
                    </body>
                
                </body>
                
                <!-- thigh 1 -->
                <body euler='0 180 0' pos='0 -0.03 0'> 
                    <inertial pos='0.03848 0 0.00397' mass='0.03921' fullinertia='0.00000539488 0.00005606744 0.00006107051 0 0.00000009813 0'/>
                    <geom type='capsule' fromto='0 0 0 0.1 0 0' size='0.01'/>
                    <geom class='mesh-import' mesh='thigh' euler='180 90 90' pos='0.1 -0.005 0'/>
                    <joint name='thigh2FL_j' type='hinge' pos='0 0 0' axis='0 1 0' range='-180 180' ref='90' armature='0.0001'/>
                
                    <body name='calfFL_short' euler='0 -120 0' pos='0.1 0.01 0'>
                        <inertial pos='0.10296 0 0.00448' mass='0.04710' fullinertia='0.00000203538 0.00019397672 0.00019542559 0 -0.00000006948 0'/>
                        <geom type='capsule' fromto='0 0 0 0.2 0 0' size='0.01' contype='2' conaffinity='2'/>
                        <joint type='hinge' pos='0 0 0' axis='0 1 0' limited='false'/>
                        <geom class='mesh-import' mesh='calf1' pos='0 0.005 0'/>
                    </body>      
            
                </body>
            </body>
    
            <!-- front right -->
            <body pos='0.2 -0.14 0'>
                <inertial pos='0 0 0' mass='0.0001' diaginertia='0.0000000001 0.0000000001 0.0000000001'/>
                <geom type='box' size='0.01 0.01 0.01'/>
            
                <!-- thigh 1 -->
                <body euler='0 0 0' pos='0 0 0'> 
                        <inertial pos='0.03848 0 0.00397' mass='0.03921' fullinertia='0.00000539488 0.00005606744 0.00006107051 0 0.00000009813 0'/>
                        <geom type='capsule' fromto='0 0 0 0.1 0 0' size='0.01'/>
                        <geom class='mesh-import' mesh='thigh' euler='180 90 90' pos='0.1 -0.005 0'/>
                        <joint name='thigh1FR_j' type='hinge' pos='0 0 0' axis='0 1 0' range='-180 180' ref='-90' armature='0.0001'/>
                    
                    <body name='calfFR_long' pos='0.1 0.01 0' euler='0 120 0'>
                        <inertial pos='0.11635 0 0.00463' mass='0.05488' fullinertia='0.00000220501 0.00027791876 0.00027939897 0 0 0'/>
                        <geom type='capsule' fromto='0 0 0 0.24 0 0' size='0.01'/>
                        <geom type='cylinder' pos='0 0.01 0' euler='0 0 90' size='0.015 0.005' condim='3' contype='2' conaffinity='2'/>
                        <geom class='mesh-import' mesh='calf2' euler='180 90 90' pos='0 -0.005 0'/>
                        <joint type='hinge' pos='0 0 0' axis='0 1 0' limited='false'/>
                    
                        <body pos='0.24 0 0'>
                            <inertial pos='0 0 0' mass='0'/>
                            <geom type='sphere' size='0.015' contype='1' conaffinity='1'/>
                            <geom class='mesh-import' mesh='foot' euler='90 0 0' pos='0.005 0 0'/>
                        </body>
                    
                    </body>
                
                </body>
                
                <!-- thigh 1 -->
                <body euler='0 180 0' pos='0 0.03 0'> 
                    <inertial pos='0.03848 0 0.00397' mass='0.03921' fullinertia='0.00000539488 0.00005606744 0.00006107051 0 0.00000009813 0'/>
                    <geom type='capsule' fromto='0 0 0 0.1 0 0' size='0.01'/>
                    <geom class='mesh-import' mesh='thigh' euler='180 90 90' pos='0.1 -0.005 0'/>
                    <joint name='thigh2FR_j' type='hinge' pos='0 0 0' axis='0 1 0' range='-180 180' ref='90' armature='0.0001'/>
                
                    <body name='calfFR_short' euler='0 -120 0' pos='0.1 -0.01 0'>
                        <inertial pos='0.10296 0 0.00448' mass='0.04710' fullinertia='0.00000203538 0.00019397672 0.00019542559 0 -0.00000006948 0'/>
                        <geom type='capsule' fromto='0 0 0 0.2 0 0' size='0.01' contype='2' conaffinity='2'/>
                        <joint type='hinge' pos='0 0 0' axis='0 1 0' limited='false'/>
                        <geom class='mesh-import' mesh='calf1' pos='0 0.005 0'/>
                    </body>      
            
                </body>
            </body>
    
            <!-- back left -->
            <body pos='-0.2 0.14 0'>
                <inertial pos='0 0 0' mass='0.0001' diaginertia='0.0000000001 0.0000000001 0.0000000001'/>
                <geom type='box' size='0.01 0.01 0.01'/>
            
                <!-- thigh 1 -->
                <body euler='0 0 0' pos='0 0 0'> 
                        <inertial pos='0.03848 0 0.00397' mass='0.03921' fullinertia='0.00000539488 0.00005606744 0.00006107051 0 0.00000009813 0'/>
                        <geom type='capsule' fromto='0 0 0 0.1 0 0' size='0.01'/>
                        <geom class='mesh-import' mesh='thigh' euler='180 90 90' pos='0.1 -0.005 0'/>
                        <joint name='thigh1BL_j' type='hinge' pos='0 0 0' axis='0 1 0' range='-180 180' ref='-90' armature='0.0001'/>
                    
                    <body name='calfBL_long' pos='0.1 -0.01 0' euler='0 120 0'>
                        <inertial pos='0.11635 0 0.00463' mass='0.05488' fullinertia='0.00000220501 0.00027791876 0.00027939897 0 0 0'/>
                        <geom type='capsule' fromto='0 0 0 0.24 0 0' size='0.01'/>
                        <geom type='cylinder' pos='0 -0.01 0' euler='0 0 90' size='0.015 0.005' condim='3' contype='2' conaffinity='2'/>
                        <geom class='mesh-import' mesh='calf2' euler='180 90 90' pos='0 -0.005 0'/>
                        <joint type='hinge' pos='0 0 0' axis='0 1 0' limited='false'/>
                    
                        <body pos='0.24 0 0'>
                            <inertial pos='0 0 0' mass='0'/>
                            <geom type='sphere' size='0.015' contype='1' conaffinity='1'/>
                            <geom class='mesh-import' mesh='foot' euler='90 0 0' pos='0.005 0 0'/>
                        </body>
                    
                    </body>
                
                </body>
                
                <!-- thigh 1 -->
                <body euler='0 180 0' pos='0 -0.03 0'> 
                    <inertial pos='0.03848 0 0.00397' mass='0.03921' fullinertia='0.00000539488 0.00005606744 0.00006107051 0 0.00000009813 0'/>
                    <geom type='capsule' fromto='0 0 0 0.1 0 0' size='0.01'/>
                    <geom class='mesh-import' mesh='thigh' euler='180 90 90' pos='0.1 -0.005 0'/>
                    <joint name='thigh2BL_j' type='hinge' pos='0 0 0' axis='0 1 0' range='-180 180' ref='90' armature='0.0001'/>
                
                    <body name='calfBL_short' euler='0 -120 0' pos='0.1 0.01 0'>
                        <inertial pos='0.10296 0 0.00448' mass='0.04710' fullinertia='0.00000203538 0.00019397672 0.00019542559 0 -0.00000006948 0'/>
                        <geom type='capsule' fromto='0 0 0 0.2 0 0' size='0.01' contype='2' conaffinity='2'/>
                        <joint type='hinge' pos='0 0 0' axis='0 1 0' limited='false'/>
                        <geom class='mesh-import' mesh='calf1' pos='0 0.005 0'/>
                    </body>      
            
                </body>
            </body>
    
            <!-- back right -->
            <body pos='-0.2 -0.14 0'>
                <inertial pos='0 0 0' mass='0.0001' diaginertia='0.0000000001 0.0000000001 0.0000000001'/>
                <geom type='box' size='0.01 0.01 0.01'/>
            
                <!-- thigh 1 -->
                <body euler='0 0 0' pos='0 0 0'> 
                        <inertial pos='0.03848 0 0.00397' mass='0.03921' fullinertia='0.00000539488 0.00005606744 0.00006107051 0 0.00000009813 0'/>
                        <geom type='capsule' fromto='0 0 0 0.1 0 0' size='0.01'/>
                        <geom class='mesh-import' mesh='thigh' euler='180 90 90' pos='0.1 -0.005 0'/>
                        <joint name='thigh1BR_j' type='hinge' pos='0 0 0' axis='0 1 0' range='-180 180' ref='-90' armature='0.0001'/>
                    
                    <body name='calfBR_long' pos='0.1 0.01 0' euler='0 120 0'>
                        <inertial pos='0.11635 0 0.00463' mass='0.05488' fullinertia='0.00000220501 0.00027791876 0.00027939897 0 0 0'/>
                        <geom type='capsule' fromto='0 0 0 0.24 0 0' size='0.01'/>
                        <geom type='cylinder' pos='0 0.01 0' euler='0 0 90' size='0.015 0.005' condim='3' contype='2' conaffinity='2'/>
                        <geom class='mesh-import' mesh='calf2' euler='180 90 90' pos='0 -0.005 0'/>
                        <joint type='hinge' pos='0 0 0' axis='0 1 0' limited='false'/>
                    
                        <body pos='0.24 0 0'>
                            <inertial pos='0 0 0' mass='0'/>
                            <geom type='sphere' size='0.015' contype='1' conaffinity='1'/>
                            <geom class='mesh-import' mesh='foot' euler='90 0 0' pos='0.005 0 0'/>
                        </body>
                    
                    </body>
                
                </body>
                
                <!-- thigh 1 -->
                <body euler='0 180 0' pos='0 0.03 0'> 
                    <inertial pos='0.03848 0 0.00397' mass='0.03921' fullinertia='0.00000539488 0.00005606744 0.00006107051 0 0.00000009813 0'/>
                    <geom type='capsule' fromto='0 0 0 0.1 0 0' size='0.01'/>
                    <geom class='mesh-import' mesh='thigh' euler='180 90 90' pos='0.1 -0.005 0'/>
                    <joint name='thigh2BR_j' type='hinge' pos='0 0 0' axis='0 1 0' range='-180 180' ref='90' armature='0.0001'/>
                
                    <body name='calfBR_short' euler='0 -120 0' pos='0.1 -0.01 0'>
                        <inertial pos='0.10296 0 0.00448' mass='0.04710' fullinertia='0.00000203538 0.00019397672 0.00019542559 0 -0.00000006948 0'/>
                        <geom type='capsule' fromto='0 0 0 0.2 0 0' size='0.01' contype='2' conaffinity='2'/>
                        <joint type='hinge' pos='0 0 0' axis='0 1 0' limited='false'/>
                        <geom class='mesh-import' mesh='calf1' pos='0 0.005 0'/>
                    </body>      
            
                </body>
            </body>
    
        </body>
    
    </worldbody>
    
    <equality>
        <connect body1='calfFL_short' body2='calfFL_long' anchor='0.2 0 0' solref='0.005 1'/>
        <connect body1='calfFR_short' body2='calfFR_long' anchor='0.2 0 0' solref='0.005 1'/>
        <connect body1='calfBL_short' body2='calfBL_long' anchor='0.2 0 0' solref='0.005 1'/>
        <connect body1='calfBR_short' body2='calfBR_long' anchor='0.2 0 0' solref='0.005 1'/>
    </equality>
    
    <actuator>
        <motor name='thigh1FL_a' joint='thigh1FL_j' gear='1' ctrllimited='true' ctrlrange='-10 10'/>
        <motor name='thigh2FL_a' joint='thigh2FL_j' gear='1' ctrllimited='true' ctrlrange='-10 10'/>
        <motor name='thigh1FR_a' joint='thigh1FR_j' gear='1' ctrllimited='true' ctrlrange='-10 10'/>
        <motor name='thigh2FR_a' joint='thigh2FR_j' gear='1' ctrllimited='true' ctrlrange='-10 10'/>
        <motor name='thigh1BL_a' joint='thigh1BL_j' gear='1' ctrllimited='true' ctrlrange='-10 10'/>
        <motor name='thigh2BL_a' joint='thigh2BL_j' gear='1' ctrllimited='true' ctrlrange='-10 10'/>
        <motor name='thigh1BR_a' joint='thigh1BR_j' gear='1' ctrllimited='true' ctrlrange='-10 10'/>
        <motor name='thigh2BR_a' joint='thigh2BR_j' gear='1' ctrllimited='true' ctrlrange='-10 10'/>
    </actuator>
    
    <sensor>
        <gyro name="body_gyro" site="bodyref" />
        <accelerometer name="body_accel" site="bodyref" />
        <framepos name="body_pos" objtype="xbody" objname="minitaur" />
    
        <jointpos name='thigh1FL_spos' joint='thigh1FL_j'/>
        <jointpos name='thigh2FL_spos' joint='thigh2FL_j'/>
        <jointvel name='thigh1FL_svel' joint='thigh1FL_j'/>
        <jointvel name='thigh2FL_svel' joint='thigh2FL_j'/>
        <jointpos name='thigh1FR_spos' joint='thigh1FR_j'/>
        <jointpos name='thigh2FR_spos' joint='thigh2FR_j'/>
        <jointvel name='thigh1FR_svel' joint='thigh1FR_j'/>
        <jointvel name='thigh2FR_svel' joint='thigh2FR_j'/>
        <jointpos name='thigh1BL_spos' joint='thigh1BL_j'/>
        <jointpos name='thigh2BL_spos' joint='thigh2BL_j'/>
        <jointvel name='thigh1BL_svel' joint='thigh1BL_j'/>
        <jointvel name='thigh2BL_svel' joint='thigh2BL_j'/>
        <jointpos name='thigh1BR_spos' joint='thigh1BR_j'/>
        <jointpos name='thigh2BR_spos' joint='thigh2BR_j'/>
        <jointvel name='thigh1BR_svel' joint='thigh1BR_j'/>
        <jointvel name='thigh2BR_svel' joint='thigh2BR_j'/>
    </sensor>
</mujoco>
