<!-- Note: Component inertias are known to be incorrect in this version -->
<mujoco model='Minitaur'>
  <compiler inertiafromgeom='false' angle='degree' eulerseq='zyx' meshdir='..\minitaur-stl'/>
  <size nuser_actuator='1' nuser_sensor='1'/>
  <option timestep='0.0005' iterations='50' solver='PGS' gravity='0 0 0'/>
  <!-- Timestep is set to 0.0005 because our controller runs at 2 kHz (-9.806) -->
  <!-- Larger values still have stable dynamics -->

  <visual>
    <quality shadowsize='4096'/>
    <map znear='0.05'/>
  </visual>

  <default>
    <joint limited='true'/>
    <geom contype='0' conaffinity='0' condim='1' solref=".005 1" solimp=".8 .8 .01" material='cassie'/>
    <motor ctrllimited='true'/>
    <mesh scale='0.01 0.01 0.01'/>
  </default>

  <asset>
    <texture type='skybox' builtin='gradient' width='128' height='128' rgb1='0.725490196078431   0.403921568627451   1.000000000000000' rgb2='1.000000000000000   0.984313725490196   0.588235294117647'/>
    <texture name='plane' type='2d' builtin='checker'  rgb1='1 0 0' rgb2='1 1 0' width='128' height='128'/>
    <material name='plane' reflectance='0.0' texture='plane' texrepeat='4 4' texuniform='true'/>
    <material name='cassie' rgba='0.003921568627451   0.803921568627451   0.996078431372549 1'/>
    <mesh name='thigh' file='Minitaur Leg Component (Thigh).stl'/>
    <mesh name='foot' file='Minitaur foot component.stl'/>
    <mesh name='calf1' file='Minitaur Leg Component (Calf no Ankle).stl'/>
    <mesh name='calf2' file='Minitaur Leg Component (Calf with Ankle).stl'/>
  </asset>

  <worldbody>
    <geom type='plane' size='1 1 1' material='plane'/>
    
    <body name='thigh1' euler='0 0 0' pos='0 0 0.3'>
      <inertial pos='0.03848 0 0.00397' mass='0.03921' fullinertia='0.00000539488 0.00005606744 0.00006107051 0 0.00000009813 0'/>
      <geom type='capsule' fromto='0 0 0 0.1 0 0' size='0.01'/>
      <!--<geom type='mesh' mesh='thigh'/>-->
      <joint type='slide' limited='false' pos='0 0 0' axis='0 0 1'/>
      <joint name='thigh1_j' type='hinge' pos='0 0 0' axis='0 1 0' range='-45 45'/>
      
      <body name='calf_long' euler='0 0 0' pos='0.1 0 0'>
        <inertial pos='0.11635 0 0.00463' mass='0.05488' fullinertia='0.00000220501 0.00027791876 0.00027939897 0 0 0'/>
        <geom type='capsule' fromto='0 0 0 -0.1 0 -0.173205' size='0.01'/>
        <joint type='hinge' pos='0 0 0' axis='0 1 0' range='-45 45'/>
        <!--<geom type='mesh' mesh='calf2'/>-->
        
        <body name='foot'>
          <!--<geom type='mesh' mesh='foot'/>-->
        </body>
      
      </body>    
      
      <body name='thigh2' euler='0 0 0' pos='0 0 0'>
        <inertial pos='-0.03848 0 0.00397' mass='0.03921' fullinertia='0.00000539488 0.00005606744 0.00006107051 0 0.00000009813 0'/>
        <geom type='capsule' fromto='0 0 0 -0.1 0 0' size='0.01'/>
        <!--<geom type='mesh' mesh='thigh'/>-->
        <joint name='thigh2_j' type='hinge' pos='0 0 0' axis='0 1 0' range='-45 45'/>
        
        <body name='calf_short' euler='0 0 0' pos='-0.1 0 0'>
          <inertial pos='0.10296 0 0.00448' mass='0.04710' fullinertia='0.00000203538 0.00019397672 0.00019542559 0 -0.00000006948 0'/>
          <geom type='capsule' fromto='0 0 0 0.1 0 -0.173205' size='0.01'/>
          <joint type='hinge' pos='0 0 0' axis='0 1 0' range='-45 45'/>
          <!--<geom type='mesh' mesh='calf1'/>-->
        </body>
      
      </body>
    
    </body>

  </worldbody>

  <equality>
    <connect body1='calf_short' body2='calf_long' anchor='0.1 0 -0.173205'/>
  </equality>

  <actuator>
    <!-- I don't know the actual numbers for these -->
    <motor name='thigh1_a' joint='thigh1_j' gear='1' ctrllimited='true' ctrlrange='-1 1'/>
    <motor name='thigh2_a' joint='thigh2_j' gear='1' ctrllimited='true' ctrlrange='-1 1'/>
  </actuator>

</mujoco>