<!-- Note: Component inertias are known to be incorrect in this version -->
<mujoco model='Minitaur'>
  <compiler inertiafromgeom='false' angle='degree' eulerseq='zyx' meshdir='..\minitaur-stl'/>
  <size nuser_actuator='1' nuser_sensor='1'/>
  <option timestep='0.0005' iterations='50' solver='PGS' gravity='0 0 0'/>
  <!-- Timestep is set to 0.0005 because our controller runs at 2 kHz (-9.806) -->
  <!-- Larger values still have stable dynamics -->

  <visual>
    <quality shadowsize='4096'/>
    <map znear='0.05'/>
  </visual>

  <default>
    <!--<joint limited='true'/>-->
    <geom contype='0' conaffinity='0' condim='1' solref=".005 1" solimp=".8 .8 .01" material='cassie'/>
    <motor ctrllimited='true'/>
    <mesh scale='0.01 0.01 0.01'/>
  </default>

  <asset>
    <texture type='skybox' builtin='gradient' width='128' height='128' rgb1='0.725490196078431   0.403921568627451   1.000000000000000' rgb2='1.000000000000000   0.984313725490196   0.588235294117647'/>
    <texture name='plane' type='2d' builtin='checker'  rgb1='1 0 0' rgb2='1 1 0' width='128' height='128'/>
    <material name='plane' reflectance='0.0' texture='plane' texrepeat='4 4' texuniform='true'/>
    <material name='cassie' rgba='0.003921568627451   0.803921568627451   0.996078431372549 1'/>
    <mesh name='thigh' file='Minitaur Leg Component (Thigh).stl'/>
    <mesh name='foot' file='Minitaur foot component.stl'/>
    <mesh name='calf1' file='Minitaur Leg Component (Calf no Ankle).stl'/>
    <mesh name='calf2' file='Minitaur Leg Component (Calf with Ankle).stl'/>
  </asset>

  <worldbody>
    <geom type='plane' size='10 10 10' material='plane'/>
    <body name='thigh2' axisangle='1 0 0 180'>
      <inertial pos='38.48 0 3.97' mass='39.21' fullinertia='0.00000539488 0.00005606744 0.00006107051 0 0.00000009813 0'/>
      <geom type='mesh' mesh='thigh'/>
      <joint type='hinge' pos='0 0 43.155' axis='0 0 1'/>
    </body>
    <body name='thigh1'>
      <inertial pos='38.48 0 3.97' mass='39.21' fullinertia='0.00000539488 0.00005606744 0.00006107051 0 0.00000009813 0'/>
      <geom type='mesh' mesh='thigh'/>
      <joint type='hinge' pos='0 0 43.155'/>
      <body name='calf_long'>
        <geom type='mesh' mesh='calf2'/>
        <!--<joint type='hinge' pos='0 0 114.205'/>-->
        <body name='foot'>
          <geom type='mesh' mesh='foot'/>
        </body>
      </body>
      <body name='calf_short'>
        <geom type='mesh' mesh='calf1'/>
      </body>
    </body>
  </worldbody>

</mujoco>