<mujoco model='Minitaur' xmlns:xi="http://www.w3.org/2001/XInclude">

  <worldbody>
    <geom type='plane' size='1 1 1' material='plane' condim='3' contype='1' conaffinity='1'/>

    <body name='hip' pos='0 0 0.35'>
      <inertial pos='0 0 0' mass='0.0001' diaginertia='0.0000000001 0.0000000001 0.0000000001'/>
      <geom type='box' size='0.01 0.01 0.01'/>
      <!--<joint type='slide' range='-0.4 10' pos='0 0 0' axis='0 0 1' stiffness='10'/>-->
      <!--<joint type='slide' limited='false' pos='0 0 0' axis='1 0 0' frictionloss='0.1'/>-->
    
      <body name='thigh1' euler='0 0 0' pos='0 0 0'>
        <inertial pos='0.03848 0 0.00397' mass='0.03921' fullinertia='0.00000539488 0.00005606744 0.00006107051 0 0.00000009813 0'/>
        <geom type='capsule' fromto='0 0 0 0.1 0 0' size='0.01'/>
        <geom class='mesh-import' mesh='thigh' euler='180 90 90' pos='0.1 -0.005 0'/>
        <joint name='thigh1_j' type='hinge' pos='0 0 0' axis='0 1 0' range='-180 180' ref='-90' armature='0.0001'/>
      
        <body name='calf_long' pos='0.1 0.01 0' euler='0 120 0'>
          <inertial pos='0.11635 0 0.00463' mass='0.05488' fullinertia='0.00000220501 0.00027791876 0.00027939897 0 0 0'/>
          <geom type='capsule' fromto='0 0 0 0.24 0 0' size='0.01'/>
          <geom type='cylinder' pos='0 0.01 0' euler='0 0 90' size='0.015 0.005' condim='3' contype='2' conaffinity='2'/>
          <geom class='mesh-import' mesh='calf2' euler='180 90 90' pos='0 -0.005 0'/>
          <joint type='hinge' pos='0 0 0' axis='0 1 0' limited='false'/>
        
          <body name='foot' pos='0.24 0 0'>
            <inertial pos='0 0 0' mass='0'/>
            <geom type='sphere' size='0.015' contype='1' conaffinity='1'/>
            <geom class='mesh-import' mesh='foot' euler='90 0 0' pos='0.005 0 0'/>
            <site name='footSensorSite' type='box' pos='0.0175 0 0' size='0.005 0.015 0.015'/>
          </body>
      
        </body>
      
      </body>
      
      <body name='thigh2' euler='0 180 0' pos='0 0.03 0'>
        <inertial pos='0.03848 0 0.00397' mass='0.03921' fullinertia='0.00000539488 0.00005606744 0.00006107051 0 0.00000009813 0'/>
        <geom type='capsule' fromto='0 0 0 0.1 0 0' size='0.01'/>
        <geom class='mesh-import' mesh='thigh' euler='180 90 90' pos='0.1 -0.005 0'/>
        <joint name='thigh2_j' type='hinge' pos='0 0 0' axis='0 1 0' range='-180 180' ref='90' armature='0.0001'/>
        
        <body name='calf_short' euler='0 -120 0' pos='0.1 -0.01 0'>
          <inertial pos='0.10296 0 0.00448' mass='0.04710' fullinertia='0.00000203538 0.00019397672 0.00019542559 0 -0.00000006948 0'/>
          <geom type='capsule' fromto='0 0 0 0.2 0 0' size='0.01' contype='2' conaffinity='2'/>
          <joint type='hinge' pos='0 0 0' axis='0 1 0' limited='false'/>
          <geom class='mesh-import' mesh='calf1' pos='0 0.005 0'/>
        </body>      
    
      </body>
    </body>

  </worldbody>

  <equality>
    <connect body1='calf_short' body2='calf_long' anchor='0.2 0 0' solref='0.005 1'/>
  </equality>

  <actuator>
    <!-- I don't know the actual numbers for these -->
    <motor name='thigh1_a' joint='thigh1_j' gear='1' ctrllimited='true' ctrlrange='-10 10'/>
    <motor name='thigh2_a' joint='thigh2_j' gear='1' ctrllimited='true' ctrlrange='-10 10'/>
  </actuator>

  <sensor>
    <jointpos name='thigh1_spos' joint='thigh1_j'/>
    <jointpos name='thigh2_spos' joint='thigh2_j'/>
    <jointvel name='thigh1_svel' joint='thigh1_j'/>
    <jointvel name='thigh2_svel' joint='thigh2_j'/>
    <touch name='foot_stouch' site='footSensorSite'/>
  </sensor>

</mujoco>
